#VRML_SIM R2025a utf8

EXTERNPROTO "https://raw.githubusercontent.com/cyberbotics/webots/R2025a/projects/objects/backgrounds/protos/TexturedBackground.proto"
EXTERNPROTO "https://raw.githubusercontent.com/cyberbotics/webots/R2025a/projects/objects/backgrounds/protos/TexturedBackgroundLight.proto"
EXTERNPROTO "https://raw.githubusercontent.com/cyberbotics/webots/R2025a/projects/objects/floors/protos/RectangleArena.proto"
EXTERNPROTO "https://raw.githubusercontent.com/cyberbotics/webots/R2025a/projects/samples/curriculum/protos/Obstacle.proto"

WorldInfo {
}
Viewpoint {
  orientation -0.39014217378445976 -0.3406555315620627 0.8554197174784464 4.424648839633912
  position -0.16750650279206813 2.1595778457850736 2.0161662868228416
}
TexturedBackground {
}
TexturedBackgroundLight {
}
RectangleArena {
}
DEF Main_Robot Robot {
  translation -0.404999 0.452361 -0.000129201
  rotation 0 0 1 0.03156500107916038
  children [
    DistanceSensor {
      translation 0 -0.05 0.04
      rotation 0 0 1 -1.57
      children [
        DEF sensor Shape {
          appearance PBRAppearance {
            baseColor 1 1 0
            metalness 0
          }
          geometry Box {
            size 0.01 0.01 0.01
          }
        }
      ]
      name "sensor_front"
      boundingObject USE sensor
      physics Physics {
      }
    }
    DistanceSensor {
      translation -0.05 0 0.03
      rotation 0 0 1 -3.141592653589793
      children [
        DEF sensor Shape {
          appearance PBRAppearance {
            baseColor 1 1 0
            metalness 0
          }
          geometry Box {
            size 0.01 0.01 0.01
          }
        }
      ]
      name "sensor_right"
      boundingObject USE sensor
      physics Physics {
      }
    }
    DistanceSensor {
      translation 0.05 0 0.03
      children [
        DEF sensor Shape {
          appearance PBRAppearance {
            baseColor 1 1 0
            metalness 0
          }
          geometry Box {
            size 0.01 0.01 0.01
          }
        }
      ]
      name "sensor_left"
      boundingObject USE sensor
      physics Physics {
      }
    }
    SliderJoint {
      jointParameters JointParameters {
      }
      endPoint Solid {
        children [
          HingeJoint {
            jointParameters HingeJointParameters {
            }
            endPoint Solid {
              children [
                Camera {
                  translation 0 0 0.1
                  rotation 0 0 1 -1.570795613280012
                  fieldOfView 1
                  width 1280
                  height 720
                  far 20
                  antiAliasing TRUE
                  recognition Recognition {
                    occlusion 0
                    frameThickness 3
                  }
                }
                Shape {
                  appearance PBRAppearance {
                    baseColor 0.7 0.6 0.3
                  }
                  geometry Cylinder {
                    height 0.02
                    radius 0.01
                  }
                }
              ]
            }
          }
          Shape {
          }
        ]
        name "solid(4)"
      }
    }
    DEF BODY_SHAPE Pose {
      translation 0 0 0.0415
      rotation 0 0 1 -3.010695613280012
      children [
        Shape {
          appearance PBRAppearance {
            baseColor 0 0 1
            roughness 1
            metalness 0
          }
          geometry Cylinder {
            height 0.08
            radius 0.045
          }
        }
      ]
    }
    DEF wheel+motor1 HingeJoint {
      jointParameters HingeJointParameters {
        position 26.805954475247958
        anchor 0.045 0 0.025
      }
      device [
        RotationalMotor {
          name "motor1"
        }
      ]
      endPoint Solid {
        translation 0.045 0 0.025
        rotation 0.5963799410278734 0.5377991620083566 0.5959052166936447 2.1540726685229337
        children [
          DEF wheel Shape {
            appearance PBRAppearance {
              baseColor 1 0 0
              roughness 1
              metalness 0
            }
            geometry Cylinder {
              height 0.01
              radius 0.025
            }
          }
        ]
        boundingObject USE wheel
        physics DEF wheel_physics Physics {
        }
      }
    }
    DEF wheel+motor2 HingeJoint {
      jointParameters HingeJointParameters {
        position 30.81993274385219
        anchor -0.045 0 0.025
      }
      device [
        RotationalMotor {
          name "motor2"
        }
      ]
      endPoint Solid {
        translation -0.045 0 0.025
        rotation 0.2819210294092649 -0.9171518679460932 0.2816966174802473 4.626807760631344
        children [
          USE wheel
        ]
        name "solid(1)"
        boundingObject USE wheel
        physics USE wheel_physics
      }
    }
    DEF eye1 Solid {
      translation -0.015 -0.045 0.068
      children [
        DEF eye Shape {
          appearance PBRAppearance {
            baseColor 1 0 0
            roughness 1
            metalness 0
          }
          geometry Box {
            size 0.005 0.005 0.005
          }
        }
      ]
      name "solid(2)"
    }
    DEF eye2 Solid {
      translation 0.0142 -0.045 0.068
      children [
        USE eye
      ]
      name "solid(3)"
    }
  ]
  boundingObject USE BODY_SHAPE
  physics Physics {
  }
  controller "drive_my_robot"
  controllerArgs [
    "left"
  ]
  supervisor TRUE
}
Obstacle {
  translation -0.277372 0.0453209 0.025
}
Obstacle {
  translation -0.239967 0.334318 0.025
  name "obstacle(4)"
}
Obstacle {
  translation 0.174911 0.368728 0.025
  name "obstacle(5)"
}
Obstacle {
  translation -0.34003 -0.116466 0.025
  name "obstacle(3)"
}
Obstacle {
  translation -0.430885 0.075342 0.025
  name "obstacle(2)"
}
Obstacle {
  translation -0.387896 0.196157 0.025
  name "obstacle(1)"
}
Robot {
  translation 0.0613475 -0.232504 2.22045e-16
  children [
    DEF REAR_LEFT_WHEEL HingeJoint {
      jointParameters HingeJointParameters {
        axis -1 0 0
        anchor -0.13 0.15 0
      }
      device [
        RotationalMotor {
          name "reaf left wheel"
        }
      ]
      endPoint Solid {
        translation -0.13 -0.15 0
        rotation -1 0 0 0
        children [
          DEF WHEEL_ROT Pose {
            rotation 0 -1 0 1.57
            children [
              Shape {
                appearance PBRAppearance {
                }
                geometry Cylinder {
                  height 0.04
                  radius 0.08
                }
              }
            ]
          }
        ]
        name "solid(1)"
        boundingObject USE WHEEL_ROT
        physics Physics {
        }
      }
    }
    DEF REAR_RIGHT_WHEEL HingeJoint {
      jointParameters HingeJointParameters {
        axis -1 0 0
        anchor 0.13 -0.15 0
      }
      device [
        RotationalMotor {
          name "rear_right_wheel"
        }
      ]
      endPoint Solid {
        translation 0.13 -0.15 0
        rotation -1 0 0 0
        children [
          DEF WHEEL_ROT Pose {
            rotation 0 -1 0 1.57
            children [
              DEF SHAPE_WHEEL_ROT Shape {
                appearance PBRAppearance {
                }
                geometry DEF WHEEL_CYL Cylinder {
                  height 0.04
                  radius 0.08
                }
              }
            ]
          }
        ]
        boundingObject USE WHEEL_ROT
        physics Physics {
        }
      }
    }
    DEF FRONT_RIGHT_WHEEL HingeJoint {
      jointParameters HingeJointParameters {
        axis -1 0 0
        anchor 0.13 0.15 0
      }
      device [
        RotationalMotor {
          name "front right wheel"
        }
      ]
      endPoint Solid {
        translation 0.13 0.15 0
        rotation -1 0 0 0
        children [
          DEF WHEEL_ROT Pose {
            rotation 0 -1 0 1.57
            children [
              Shape {
                appearance PBRAppearance {
                }
                geometry Cylinder {
                  height 0.04
                  radius 0.08
                }
              }
            ]
          }
        ]
        name "solid(2)"
        boundingObject USE WHEEL_ROT
        physics Physics {
        }
      }
    }
    DEF FRONT_LEFT_WHEEL HingeJoint {
      jointParameters HingeJointParameters {
        axis -1 0 0
        anchor -0.13 0.15 0
      }
      device [
        RotationalMotor {
          name "front_left_wheel"
        }
      ]
      endPoint Solid {
        translation -0.13 0.15 0
        rotation -1 0 0 0
        children [
          Pose {
            rotation 0 -1 0 1.57
            children [
              USE SHAPE_WHEEL_ROT
            ]
          }
        ]
        name "solid(3)"
        boundingObject USE WHEEL_ROT
        physics Physics {
        }
      }
    }
    DEF BODY_SHAPE Shape {
      appearance PBRAppearance {
      }
      geometry Box {
        size 0.2 0.4 0.1
      }
    }
  ]
  name "robot(1)"
  boundingObject USE sensor
  physics Physics {
  }
  controller "four_wheels_controller"
}
