#VRML_SIM R2025a utf8

EXTERNPROTO "https://raw.githubusercontent.com/cyberbotics/webots/R2025a/projects/objects/backgrounds/protos/TexturedBackground.proto"
EXTERNPROTO "https://raw.githubusercontent.com/cyberbotics/webots/R2025a/projects/objects/backgrounds/protos/TexturedBackgroundLight.proto"
EXTERNPROTO "https://raw.githubusercontent.com/cyberbotics/webots/R2025a/projects/objects/floors/protos/RectangleArena.proto"
EXTERNPROTO "https://raw.githubusercontent.com/cyberbotics/webots/R2025a/projects/appearances/protos/CorrodedMetal.proto"

WorldInfo {
}
Viewpoint {
  orientation 0.14468705627637007 -0.7249804701074275 -0.6734010496790838 5.706925203935171
  position -0.6086055320976119 0.35464872286399596 0.22851815298790043
}
TexturedBackground {
}
TexturedBackgroundLight {
}
RectangleArena {
}
Robot {
  translation -0.131935 0.427065 -0.000206212
  rotation -0.9999998353581819 0.0005166127332331788 0.0002497896974206416 0.02918924374266875
  children [
    VacuumGripper {
      children [
        Pose {
          translation 0 0 0.09
          children [
            Shape {
              appearance CorrodedMetal {
              }
              geometry Cylinder {
                height 0.02
                radius 0.03
              }
            }
          ]
        }
      ]
    }
    DEF BODY_SHAPE Pose {
      translation 0 0 0.0415
      rotation 0 0 1 -3.010695613280012
      children [
        Shape {
          appearance PBRAppearance {
            baseColor 0 0 1
            roughness 1
            metalness 0
          }
          geometry Cylinder {
            height 0.08
            radius 0.045
          }
        }
      ]
    }
    HingeJoint {
      jointParameters HingeJointParameters {
        position 6.224517850528979
        anchor 0.045 0 0.025
      }
      device [
        RotationalMotor {
          name "motor1"
        }
      ]
      endPoint Solid {
        translation 0.045 0 0.025
        rotation 0.029340249966997394 -0.9991394644437528 0.029316894837703184 4.712324401234279
        children [
          DEF wheel Shape {
            appearance PBRAppearance {
              baseColor 1 0 0
              roughness 1
              metalness 0
            }
            geometry Cylinder {
              height 0.01
              radius 0.025
            }
          }
        ]
        boundingObject USE wheel
        physics DEF wheel_physics Physics {
        }
      }
    }
    HingeJoint {
      jointParameters HingeJointParameters {
        position 6.224517840408927
        anchor -0.045 0 0.025
      }
      device [
        RotationalMotor {
          name "motor2"
        }
      ]
      endPoint Solid {
        translation -0.045 0 0.025
        rotation 0.02934025502234152 -0.9991394641470833 0.029316899889023182 4.712324400937356
        children [
          USE wheel
        ]
        name "solid(1)"
        boundingObject USE wheel
        physics USE wheel_physics
      }
    }
    Solid {
      translation -0.015 -0.045 0.068
      children [
        DEF eye Shape {
          appearance PBRAppearance {
            baseColor 1 0 0
            roughness 1
            metalness 0
          }
          geometry Box {
            size 0.005 0.005 0.005
          }
        }
      ]
      name "solid(2)"
    }
    Solid {
      translation 0.0015 -0.045 0.068
      children [
        USE eye
      ]
      name "solid(3)"
    }
  ]
  boundingObject USE BODY_SHAPE
  physics Physics {
  }
  controller "drive_my_robot"
}
